Workbook

Sheet CARIK
A1: MATRIK RENCANA KEGIATAN
A3: Nama | C3: : | D3: MUH MASRURI MUSTOFA, S.T
A4: Jabatan | C4: : | D4: CARIK
A6: No. | B6: Rencana kegiatan | D6: Output | E6: Target | S6: Jumlah e s/d p
G7: Jan. | H7: Feb. | I7: Maret | J7: April | K7: Mei | L7: Juni | M7: Juli | N7: Agust. | O7: Sept. | P7: Okt. | Q7: Nov. | R7: Des.
A8: a | B8: b | D8: c | E8: d | G8: e | H8: f | I8: g | J8: h | K8: i | L8: j | M8: k | N8: l | O8: m | P8: n | Q8: o | R8: p | S8: q
T9: Catatan:
A10: 1 | B10: Pengoordinasian administrasi Pemerintahan Kalurahan | C10: a | D10: Terlaksananya pencermatan tata naskah surat sebelum dibubuhkan paraf dan/atau tanda tangan (contoh: pencermatan Surat Keputusan sebelum diparaf/tanda tangan). | E10: 16 | F10: Surat/dokumen | O10: 4 | P10: 4 | Q10: 4 | R10: 4 | S10: =SUM(H10:R10) -> 16 | T10: 1. Jumlah target disesuaikan dengan kondisi masing-masing kalurahan
C11: b | D11: Terlaksananya koordinasi dalam rangka inventarisasi arsip, surat, dan lain-lain. (contoh: koordinasi penyimpanan arsip kepada pamong kalurahan) | E11: 4 | F11: kali | O11: 1 | P11: 1 | Q11: 1 | R11: 1 | S11: =SUM(H11:R11) -> 4
C12: c | D12: Terlaksananya koordinasi dalam penataan administrasi pamong kalurahan (contoh: koordinasi kepada pamong terkait dengan pengisian laporan kinerja, penyusunan dokumen-dokumen kelengkapan BLT DD, dll) | E12: 8 | F12: kali | O12: 2 | P12: 2 | Q12: 2 | R12: 2 | S12: =SUM(H12:R12) -> 8
C13: d | D13: Terlaksanannya koordinasi dalam rangka penyedian sarana dan prasarana kalurahan (contoh: koordinasi kepada kaur panata laksana sarta pangripta untuk membeli sapu, merencanakan di kegiatan APBDES untuk dianggarakan belanja seragam) | E13: 4 | F13: kali | O13: 1 | P13: 1 | Q13: 1 | R13: 1 | S13: =SUM(H13:R13) -> 4
C14: e | D14: Terlaksananya koordinasi pelaksanaan Musyawarah, Pertemuan, Rapat, dll. (contoh: Koordinasi Pelaksaan Muskal, Musrenbang, Rakor, dll) | E14: 24 | F14: kali | O14: 6 | P14: 6 | Q14: 6 | R14: 6 | S14: =SUM(H14:R14) -> 24
C15: f | D15: Terlaksananya koordinasi pelaksanaan inventarisasi aset kalurahan (contoh: koordinasi kepada Palapa untuk melaksanakan kegiatan inventarisasi aset Kalurahan Janten) | E15: 1 | F15: kali | R15: 1 | S15: =SUM(H15:R15) -> 1
C17: h | D17: Terlaksana koordinasi fasilitasi pelayanan umum (contoh: Koordinasi kepada Kaur Palapa untuk melaksanakan pelayanan menggunakan SID) | E17: 4 | F17: kali | O17: 1 | P17: 1 | Q17: 1 | R17: 1 | S17: =SUM(H17:R17) -> 4 | T17: solar, pertalite,(xstar)
C18: i | D18: Terlaksananya pembubuhan paraf dalam SPJ dan/atau SPP kegiatan dan memberikan koreksi apabila ditemukan ketidaksesuaian. (contoh: paraf pada SPP siltap Pamong) | E18: 32 | F18: dokumen | O18: 8 | P18: 8 | Q18: 8 | R18: 8 | S18: =SUM(H18:R18) -> 32
C19: j | D19: Terlaksananya koordinasi penganggaran dari berbagai sumber dan kegiatan kasi dan/atau kaur. (contoh: menghitung prosentase prioritas wajib yang harus dipenuhi pada tiap penganggaran dan kegiatan-kegiatan lainnya) | E19: 8 | F19: kali | O19: 4 | Q19: 4 | S19: =SUM(H19:R19) -> 8
C20: k | D20: Terlaksanannya koordinasi pelaksanaan pembuatan proposal usulan Dana Keistimewaan dan Musyawarah/pertemuan lain terkait dengan Usulan Dana Keistimewaan. (contoh: koordinasi pembuatan proposa papan nama) | E20: 2 | F20: kali | O20: 2 | S20: =SUM(H20:R20) -> 2
A21: 2 | B21: Koordinasi, pengendalian dan evaluasi terhadap perencanaan dan pelaksanaan kegiatan Pemerintah Kalurahan. | C21: a | D21: Terlaksananya koordinasi pengendalian dan evaluasi kegiatan Kasi dan/atau kaur. (contoh: koordinasi kegiatan siltap segera dibuat kelengkapan supaya dapat segera cair, kegiatan musyawarah kalurahan supaya sesuai dengan agenda waktu dalam perundang-undangan yang berlaku) | E21: 16 | F21: kali | O21: 4 | P21: 4 | Q21: 4 | R21: 4 | S21: =SUM(H21:R21) -> 16
A22: 3 | B22: Pelaksanaan pengelolaan keuangan. | C22: a | D22: Terlaksananya koordinasi penyusunan dan pelaksanaan kebijakan anggaran pendapatan dan belanja kalurahan (Koordinasi pelaksanaan kegiatan sinkronisasi dengan sumber dana) | E22: 4 | F22: kali | P22: 2 | R22: 2 | S22: =SUM(H22:R22) -> 4
C23: b | D23: Terlaksananya koordinasi penyusunan Peraturan Lurah Penjabaran APB Kalurahan dan/atau perubahan Penjabaran APB Kalurahan, dalam rangka singkronisasi antara kebutuhan dan anggaran. (contoh: koordinasi terkait dengan perubahan kegiatan dan sumber dana perubahan tersebut berasal dari kegiatan apa) | E23: 3 | F23: kali | O23: 1 | Q23: 1 | R23: 1 | S23: =SUM(H23:R23) -> 3
C24: c | D24: Terlaksananya koordinasi penyusunan Pertanggungjawaban pelaksanaan anggaran pendapatan dan belanja kalurahan. (contoh: koordinasi kegiatan penyusunan laporan laporan akhir tahun, LPPD, dan LKPD) | E24: 4 | F24: kali | R24: 4 | S24: =SUM(H24:R24) -> 4
C25: d | D25: Terlaksananya Tugas Pamong Kalurahan Lain yang menjalankan tugas Pelaksana Pengelolaan Keuangan Kalurahan (PPKK) (contoh: koordinasi agenda kegiatan masing-masing kasi dan/atau kaur sesuai dengan RAB) | E25: 4 | F25: kali | O25: 1 | P25: 1 | Q25: 1 | R25: 1 | S25: =SUM(H25:R25) -> 4
C26: e | D26: Terlaksananya verifikasi terhadap Dokumen Pelaksanaan Anggaran (DPA), Dokumen Pelaksanaan Perubahan Anggaran (DPPA), Dokumen Pelaksanaan Anggaran Lanjutan (DPAL), Rencana Anggaran Kas Kalurahan (RAK Kalurahan), Surat Perintah Pembayaran (SPP) dan bukti penerimaan dan pengeluaran anggaran pendapatan dan belanja kalurahan. | E26: 24 | F26: kali | O26: 6 | P26: 6 | Q26: 6 | R26: 6 | S26: =SUM(H26:R26) -> 24
A27: 4 | B27: Memberikan saran dan pertimbangan kepada Lurah mengenai kebijakan yang akan diambil | C27: a | D27: Terlaksanannya penyampaian saran dan pertimbangan kepada Lurah mengenai kebijakan yang akan diambil | E27: 8 | F27: kali | O27: 2 | P27: 2 | Q27: 2 | R27: 2 | S27: =SUM(H27:R27) -> 8
A28: 5 | B28: Pelaksanaan tugas lain yang diberikan oleh Lurah | C28: a | D28: Terlaksananya tugas disposisi surat, undangan dan/atau tugas lain dari Lurah dan melaporkan hasil pelaksanaannya kepada Lurah. | E28: 8 | F28: laporan | O28: 2 | P28: 2 | Q28: 2 | R28: 2 | S28: =SUM(H28:R28) -> 8
C29: b | D29: Terlaksananya tugas menjadi bagian dalam Tim Pelaksana Kegiatan (TPK), dan/atau Tim lainnya berdasarkan Surat Keputusan. (contoh: Masuk dalam TPK Penyusun RKP Kalurahan) | E29: 1 | F29: tim | O29: 1 | S29: =SUM(H29:R29) -> 1
C30: c | D30: Tersusunnya arsip setiap dokumen dan/atau berkas atas bidang tugasnya (contoh: Mengarsipkan dokumen SPP-SPJ, berita acara, perjanjian, dll pada semua kegiatan bidang tugasnya dengan tertib sehingga apabila dibutuhkan setiap waktu siap untuk disajikan) | E30: 4 | F30: arsip | O30: 1 | P30: 1 | Q30: 1 | R30: 1 | S30: =SUM(H30:R30) -> 4
C31: d | D31: Terlaksanannya pengantaran surat/dokumen berdasarkan tugas yang diberikan oleh Lurah. | E31: 2 | F31: dokumen | R31: 2 | S31: =SUM(H31:R31) -> 2
C32: e | D32: Terlaksananya monitoring dan evaluasi program kegiatan sesuai bidang tugasnya dan melaporkannya kepada lurah setiap bulan. (contoh: Melaporkan kepada lurah pelaksanaan program kegiatannya, termasuk permasalahan, hambatan, serta solusinya) | E32: 8 | F32: laporan | O32: 2 | P32: 2 | Q32: 2 | R32: 2 | S32: =SUM(H32:R32) -> 8
C33: f | D33: Mengikuti Musyawarah Padukuhan (Musduk) | E33: 0 | F33: kali | S33: =SUM(H33:R33) -> 0
C34: g | D34: Mengikuti Musyawarah Kalurahan (Muskal) | E34: 0 | F34: kali | S34: =SUM(H34:R34) -> 0
C35: h | D35: Mengikuti Musyawarah Rencana Pembangunan (Musrenbang) | E35: 0 | F35: kali | S35: =SUM(H35:R35) -> 0
C36: i | D36: Terlaksananya pelaksanaan tugas lain yang diberikan oleh Lurah selain yang sudah tercantum dalam output kegiatan ini dan melaporakan hasil pelaksanaannya kepada lurah. | E36: 4 | F36: laporan | O36: 1 | P36: 1 | Q36: 1 | R36: 1 | S36: =SUM(H36:R36) -> 4
C37: j | D37: Penulisan Informasi/berita tentang kegiatan, potensi atau prestasi sesuai bidang tugasnya | E37: 4 | F37: kali | O37: 1 | P37: 1 | Q37: 1 | R37: 1 | S37: =SUM(H37:R37) -> 4
A39: JUMLAH MASING-MASING BULAN | E39: =SUM(E10:E38) -> 197 | H39: =SUM(H10:H38) -> 0 | I39: =SUM(I10:I38) -> 0 | J39: =SUM(J10:J38) -> 0 | K39: =SUM(K10:K38) -> 0 | L39: =SUM(L10:L38) -> 0 | M39: =SUM(M10:M38) -> 0 | N39: =SUM(N10:N38) -> 0 | O39: =SUM(O10:O38) -> 51 | ... S39: =SUM(S10:S38) -> 197
F41: =E39/5 -> 39.4 | O41: Janten, 10 agustus 2026
O42: Yang berjanji
B43: LURAH KALIDENGEN | O43: CARIK
B46: SUNARDI | O46: =D3 -> MUH MASRURI MUSTOFA, S.T
H49: =SUM(H39:R39) -> 197
...

Sheet KAMITUWA
A1: MATRIK RENCANA KEGIATAN
A3: Nama | C3: : | D3: SUMARDI
A4: Jabatan | C4: : | D4: KAMITUWA
A6: No. | B6: Rencana kegiatan | D6: Output | E6: Target | G6: Waktu | S6: Jumlah e s/d p
G7: Jan. | H7: Feb. | I7: Maret | J7: April | K7: Mei | L7: Juni | M7: Juli | N7: Agust. | O7: Sept. | P7: Okt. | Q7: Nov. | R7: Des.
A8: a | B8: b | D8: c | E8: d | G8: e | H8: f | I8: g | J8: h | K8: i | L8: j | M8: k | N8: e | O8: f | P8: g | Q8: h | R8: i | S8: j
A10: 1 | B10: Perencanaan, pelaksanaan, pengendalian dan evaluasi pelaksanaan kegiatan sosial kemasyarakatan | C10: a | D10: Terlaksananya penyuluhan dan motivasi di dalam forum pertemuan terhadap pelaksanaan hak dan kewajiban masyarakat. (contoh: penyampaian informasi tentang gaya hidup sehat, pelayanan di kalurahan, pajak, gotong royong dll) | E10: 10 | F10: kali | O10: 2 | P10: 2 | Q10: 4 | R10: 2 | S10: =SUM(N10:R10) -> 10
C11: b | D11: Tersusunnya Rencana Anggaran Biaya (RAB) dalam perencanaan kegiatan tahun berikutnya maupun Perubahan APBKAL di tahun berjalan. | E11: 8 | F11: kegiatan | O11: 4 | Q11: 4 | S11: =SUM(N11:R11) -> 8
C12: c | D12: Kehadiran di kegiatan latihan, pementasan atau kegiatan latihan serta memberikan motivasi maupun informasi berkaitan dengan kegiatan kebudayaan kepada kelompok tersebut. (contoh: menghadiri kegiatan latihan Sholawat, Ketoprak, hadroh, dll kemudian memberikan informasi mengenai informasi/regulasi terbaru tentang prosedur pengajuan proposal dalam rangka pengembangan kegiatan tersebut | E12: 8 | F12: kali | O12: 2 | P12: 2 | Q12: 2 | R12: 2 | S12: =SUM(N12:R12) -> 8
A13: 2 | B13: Penyuluhan dan motivasi di bidang keagamaan, ketenagakerjaan, pemberdayaan perempuan, perlindungan anak, keluarga berencana, pendidikan, kesehatan, pemuda, olahraga, karang taruna dan penanggulangan kemiskinan | C13: a | D13: Terlaksananya penyampaian Informasi ke Masyarakat dalam sebuah forum pertemuan terkait dengan bidang keagamaan, ketenagakerjaan, pemberdayaan perempuan, perlindungan anak, keluarga berencana, Pendidikan, kesehatan, pemuda, olahraga, karangtaruna dan penanggulangan kemiskinan. (contoh: Menghadiri pertemuan Kegiatan Posyandu, Kader, IP3M/PAUD, dll., kemudian menyampaikan informasi terkait tata cara/prosedur pengajuan BPJS PBI | E13: 8 | F13: kali | O13: 2 | P13: 2 | Q13: 2 | R13: 2 | S13: =SUM(N13:R13) -> 8
A14: 3 | B14: Kegiatan urusan keistimewaan bidang kebudayaan | C14: a | D14: Terlaksananya pendampingan terkait pelaksanaan kegiatan kebudayaan yang ada di kalurahan (contoh: Menghadiri latihan kegiatan Merti Padukuhan, Wiwitan, Puputan, Tingkepan, dll., sehingga mengetahui terkait dengan eksistensi kegiatan tersebut yang dapat digunakan sebagai dasar perencanaan kegiatan di APBKAL maupun kegiatan dari dinas terkait) | E14: 5 | F14: kegiatan | O14: 1 | P14: 1 | Q14: 2 | R14: 1 | S14: =SUM(N14:R14) -> 5
A15: 4 | B15: Pelaksanaan Kegiatan Anggaran | C15: a | D15: Terlaksananya Penyelenggaraan PAUD/TK/TPA/TKA/TPQ/Madrasah Non-Formal Milik Kalurahan Janten* | E15: 4 | F15: bulan | O15: 1 | P15: 1 | Q15: 1 | R15: 1 | S15: =SUM(N15:R15) -> 4
C16: b | D16: Terlaksananya Penyelenggaraan Posyandu* | E16: 12 | F16: Kali | O16: 3 | P16: 3 | Q16: 3 | R16: 3 | S16: =SUM(N16:R16) -> 12
C17: c | D17: Terlaksananya Penyuluhan dan Pelatihan Bidang Kesehatan* | E17: 1 | F17: kegiatan | O17: 1 | S17: =SUM(N17:R17) -> 1
C18: d | D18: Menghadiri pertemuan Rutin PKK | E18: 4 | F18: kegiatan | O18: 1 | P18: 1 | Q18: 1 | R18: 1 | S18: =SUM(N18:R18) -> 4
C19: e | D19: Menghadiri pertemuan Rutin Karangtaruna | E19: 4 | F19: kegiatan | O19: 1 | P19: 1 | Q19: 1 | R19: 1 | S19: =SUM(N19:R19) -> 4
C20: f | D20: Menghadiri pertemuan Kader Posyandu | E20: 4 | F20: kegiatan | O20: 1 | P20: 1 | Q20: 1 | R20: 1 | S20: =SUM(N20:R20) -> 4
C21: g | D21: Terlaksananya Penyaluran Honor Rois | E21: 4 | F21: kegiatan | O21: 1 | P21: 1 | Q21: 1 | R21: 1 | S21: =SUM(N21:R21) -> 4
C22: h | D22: Terlaksananya Program Beasiswa | E22: 1 | F22: kegiatan | O22: 1 | S22: =SUM(O22:R22) -> 1
C23: i | D23: Monev Beasiswa | E23: 1 | F23: kegiatan | P23: 1 | S23: =SUM(N23:R23) -> 1
C24: j | D24: Terlaksananya Keadaan Mendesak (Penyaluran BLT)* | E24: 4 | F24: bulan | O24: 1 | P24: 1 | Q24: 1 | R24: 1 | S24: =SUM(N24:R24) -> 4
A25: 5 | B25: Pelayanan sesuai bidang tugasnya | C25: a | D25: Terlaksananya pelayanan kepada warga masyarakat terkait dengan pernikahan. (contoh: Melayani konsultasi warga tentang tata cara/prosedur persyaratan-persyaratan pernikahan, izin melaksanakan Pengajian lainnya) | E25: 8 | F25: kali | O25: 2 | P25: 2 | Q25: 2 | R25: 2 | S25: =SUM(N25:R25) -> 8
C26: b | D26: Terlaksananya pelayanan warga masyarakat terkait dengan bidang keagamaan, budaya, olahraga, karangtaruna, social, keluarga, pendidikan, pemberdayaan perempuan, perlindungan anak, dll. (contoh: Melayani konsultasi kelompok-kelompok budaya, olahraga, keagamaan, dll terkait tata cara/prosedur izin kegiatan, pengajuan proposal, dll) | E26: 4 | F26: kali | O26: 1 | P26: 1 | Q26: 1 | R26: 1 | S26: =SUM(N26:R26) -> 4
A27: 6 | B27: Mencari, mengumpulkan, menghimpun dan mengolah serta menyajikan data dan informasi yang berhubungan dengan bidang tugasnya | C27: a | D27: Tersusunnya dan terarsipkannya himpunan informasi mengenai regulasi, dan informasi terbaru sesuai bidang tugasnya, dan melaksanakan serta mengarsipkannya dengan tertib. (contoh: Mencari salinan landasan hukum tentang Posyandu, PAUD dll) | E27: 2 | F27: dokumen | O27: 1 | R27: 1 | S27: =SUM(N27:R27) -> 2
C28: b | D28: Tersusunnya dan terarsipkannya himpunan informasi mengenai Kepemilikan Jaminan kesehatan masyarakat | E28: 2 | F28: Bulan | Q28: 1 | R28: 1 | S28: =SUM(N28:R28) -> 2
A29: 7 | B29: Membuat laporan pelaksanaan seluruh kegiatan sesuai bidang tugasnya | C29: a | D29: Tersusunnya laporan pelaksanaan kegiatan kepada Lurah sesuai dengan bidang tugasnya (contoh: Menyampaikan laporan secara lisan tertulis kepada Lurah tentang sosial kemasyarakatan, keagaman, kesehatan dan kebudayaan misalnya pelaksanaan PMT, Tracing kesehatan , pemantuan jentik dll) | E29: 1 | F29: laporan | P29: 1 | S29: =SUM(N29:R29) -> 1
A30: 8 | B30: Memberikan saran dan pertimbangan kepada Lurah mengenai kebijakan dan tindakan yang akan diambil | C30: a | D30: Terlaksananya penyampaian saran dan pertimbangan kepada Lurah mengenai kebijakan yang akan diambil (contoh: Memberikan saran dan pertimbangan mengenai kebijakan pelaksanaan merti kalurahan, hari jadi kalurahan, kegiatan peringatan HUT RI, dll) | E30: 1 | F30: kali | Q30: 1 | S30: =SUM(N30:R30) -> 1
A31: 9 | B31: Melaksanakan Tugas lain yang diberikan oleh Lurah | C31: a | D31: Terlaksananya tugas disposisi surat, undangan dan/atau tugas lain dari Lurah dan melaporkan hasil pelaksanaannya kepada Lurah. | E31: 1 | F31: laporan | P31: 1 | S31: =SUM(N31:R31) -> 1
C32: b | D32: Terlaksananya tugas menjadi bagian dalam Tim Pelaksana Kegiatan (TPK), dan/atau Tim lainnya berdasarkan Surat Keputusan. (contoh: Masuk dalam TPK Kegiatan Posyandu) | E32: 2 | F32: tim | O32: 1 | R32: 1 | S32: =SUM(N32:R32) -> 2
C33: c | D33: Tersusunnya arsip setiap dokumen dan/atau berkas atas bidang tugasnya (contoh: Mengarsipkan dokumen SPP-SPJ, berita acara, perjanjian, dll pada semua kegiatan bidang tugasnya dengan tertib sehingga apabila dibutuhkan setiap waktu siap untuk disajikan) | E33: 10 | F33: dokumen | O33: 3 | P33: 3 | Q33: 2 | R33: 2 | S33: =SUM(N33:R33) -> 10
C34: d | D34: Terlaksanannya pengantaran surat/dokumen berdasarkan tugas yang diberikan oleh Lurah. | E34: 1 | F34: dokumen | R34: 1 | S34: =SUM(N34:R34) -> 1
C35: e | D35: Terlaksananya penyusunan laporan pelaksanaan kegiatan sesuai bidang tugasnya setiap semester dan untuk pertanggungjawaban pelaksanaan APBKAL selama 1 tahun anggaran . (contoh: laporan penggunaan anggaran kegiatan dan sisa anggaran kegiatan, beserta alasannya apabila ada sisa anggaran) | E35: 1 | F35: laporan | R35: 1 | S35: =SUM(N35:R35) -> 1
C36: f | D36: Terlaksananya penyusunan dan mengajukan SPP dan SPJ kegiatan kepada bendahara maksimal 5 hari kerja setelah kegiatan selesai dilaksanakan. | E36: 30 | F36: SPP | O36: 8 | P36: 7 | Q36: 7 | R36: 8 | S36: =SUM(N36:R36) -> 30
C37: g | D37: Terlaksananya monitoring dan evaluasi program kegiatan sesuai bidang tugasnya dan melaporkannya kepada lurah setiap bulan. (contoh: Melaporkan kepada lurah pelaksanaan program kegiatannya, termasuk permasalahan, hambatan, serta solusinya) | E37: 2 | F37: laporan | O37: 1 | R37: 1 | S37: =SUM(N37:R37) -> 2
C38: h | D38: Mengikuti pertemuan di Padukuhan dan atau Musduk | E38: 1 | F38: kali | Q38: 1 | S38: =SUM(N38:R38) -> 1
C39: i | D39: Mengikuti Musyawarah Kalurahan (Muskal) | E39: 1 | F39: kali | Q39: 1 | S39: =SUM(N39:R39) -> 1
C40: j | D40: Mengikuti Musyawarah Rencana Pembangunan (Musrenbang) | E40: 1 | F40: kali | O40: 1 | S40: =SUM(N40:R40) -> 1
C41: k | D41: Terlaksananya sambutan wakil keluarga atau sebutan lain dalam upacara pernikahan, lamaran, lelayu, dll . (contoh: sambutan wakil keluarga upacara pemberangkatan jenazah) | E41: 5 | F41: kali | O41: 2 | P41: 1 | Q41: 1 | R41: 1 | S41: =SUM(N41:R41) -> 5
C42: l | D42: Terlaksananya pelaksanaan tugas lain yang diberikan oleh Lurah selain yang sudah tercantum dalam output kegiatan ini. | E42: 1 | F42: laporan | R42: 1 | S42: =SUM(N42:R42) -> 1
C43: m | D43: mengikuti rapat koordinasi dan atau apel rutin | E43: 20 | F43: Kali | O43: 5 | P43: 5 | Q43: 5 | R43: 5 | S43: =SUM(N43:R43) -> 20
...

Sheet DAnarta
A1: MATRIK RENCANA KEGIATAN
A4: Nama | C4: : | D4: VIKI WULANDARI
A5: Jabatan | C5: : | D5: DANARTA
A7: No. | B7: Rencana kegiatan | D7: Output | E7: Target | S7: Jumlah e s/d p
G8: Jan. | H8: Feb. | I8: Maret | J8: April | K8: Mei | L8: Juni | M8: Juli | N8: Agust. | O8: Sept. | P8: Okt. | Q8: Nov. | R8: Des.
A9: a | B9: b | D9: c | E9: d | G9: e | H9: f | I9: g | J9: h | K9: i | L9: j | M9: k | N9: l | O9: m | P9: n | Q9: o | R9: p | S9: q
A11: 1 | B11: Perencanaan, pelaksanaan, pengendalian dan evaluasi pelaksanaan urusan keuangan. | C11: a | D11: Tersusunnya Rencana Anggaran Biaya (RAB) dalam perencanaan kegiatan tahun berikutnya maupun Perubahan APBKAL di tahun berjalan. | E11: 2 | F11: kegiatan | P11: 1 | R11: 1 | S11: =SUM(N11:R11) -> 2
C12: b | D12: Membuat Buku Kas Umum | E12: 4 | F12: bulan | O12: 1 | P12: 1 | Q12: 1 | R12: 1 | S12: =SUM(N12:R12) -> 4
C13: c | D13: Membuat Buku Kas Tunai | E13: 4 | F13: bulan | O13: 1 | P13: 1 | Q13: 1 | R13: 1 | S13: =SUM(N13:R13) -> 4
C14: d | D14: Membuat Buku bantu Bank | E14: 4 | F14: bulan | O14: 1 | P14: 1 | Q14: 1 | R14: 1 | S14: =SUM(N14:R14) -> 4
C15: e | D15: Membuat Buku bantu Pajak | E15: 4 | F15: bulan | O15: 1 | P15: 1 | Q15: 1 | R15: 1 | S15: =SUM(N15:R15) -> 4
C16: f | D16: Membuat Buku bantu Kegiatan | E16: 4 | F16: bulan | O16: 1 | P16: 1 | Q16: 1 | R16: 1 | S16: =SUM(N16:R16) -> 4
C17: g | D17: Membuat Buku Penutupan Kas | E17: 4 | F17: bulan | O17: 1 | P17: 1 | Q17: 1 | R17: 1 | S17: =SUM(N17:R17) -> 4
C18: h | D18: Berkoordinasi bersama carik dan pamong melakukan Penyusunan Dokumen Keuangan Kalurahan (misal: memberi masukan terkait laporan keuangan sehingga menjadi dasar penyusunan APB Kalurahan/APB Kalurahan Perubahan/LPJ APB Kalurahan, dll)* | E18: 5 | F18: Dokumen | O18: 1 | P18: 3 | R18: 1 | S18: =SUM(N18:R18) -> 5
C19: i | D19: Tersalurnya Siltap tujangan Pamong dan BPK | E19: 4 | F19: bulan | O19: 1 | P19: 1 | Q19: 1 | R19: 1 | S19: =SUM(N19:R19) -> 4
C20: j | D20: Melakukan Pemotongan Pajak, input biling, menyetorkan dan mencatatkan pada aplikasi siskeudes Paling lambat 5 hari bulan berikutnya | E20: 15 | F20: bulan | O20: 3 | P20: 4 | Q20: 4 | R20: 4 | S20: =SUM(N20:R20) -> 15
C21: k | D21: Mengajukan permohonan pencairan Alokasi Dana desa (ADD) | E21: 4 | F21: Bulan | O21: 1 | P21: 1 | Q21: 1 | R21: 1 | S21: =SUM(N21:R21) -> 4
C22: l | D22: Membuat rencana pencairan, melakukan transaksi dan membukukan pada aplikasi siskeudes | E22: 32 | F22: Kali | O22: 8 | P22: 8 | Q22: 8 | R22: 8 | S22: =SUM(N22:R22) -> 32
D23: Melakukan transaksi dengan menggunakan aplikasi smartdesaku | E23: 10 | F23: Kali | O23: 3 | P23: 2 | Q23: 2 | R23: 3 | S23: =SUM(N23:R23) -> 10
A24: 2 | B24: Menyusun laporan pertanggungjawaban realisasi pelaksanaan anggaran pendapatan dan belanja kalurahan | C24: a | D24: Membuat laporan realisasi bulanan | E24: 4 | F24: bulan | O24: 1 | P24: 1 | Q24: 1 | R24: 1 | S24: =SUM(N24:R24) -> 4
C25: b | D25: Membuat laporan realisasi semester II | E25: 1 | F25: kali | R25: 1 | S25: =SUM(N25:R25) -> 1
C26: c | D26: Membuat Laporan realisasi akhir tahun | E26: 1 | F26: kali | R26: 1 | S26: =SUM(N26:R26) -> 1
A27: 3 | B27: Melakukan penatausahaan keuangan yang meliputi menerima menyimpan, menyetorkan/membayar, menatausahakan dan mempertanggungjawabkan penerimaan pendapatan Kalurahan dan pengeluaran dalam rangka pelaksanaan anggaran pendapatan dan belanja kalurahan | C27: a | D27: Menerima, Menyetorkan dan melakukakan pencatatan pendapatan kalurahan pada aplikasi siskeudes | E27: 2 | F27: Kali | P27: 2 | S27: =SUM(N27:R27) -> 2
A28: 4 | B28: Mencari, mengumpulkan, menghimpun dan mengolah serta menyajikan data dan informasi yang berhubungan dengan bidang tugasnya | C28: a | D28: Tersusunnya dan terarsipkannya himpunan informasi mengenai regulasi, dan informasi terbaru sesuai bidang tugasnya, dan melaksanakan serta mengarsipkannya dengan tertib. (contoh: Pencarian Permendesa tentang Prioritas Penggunaan Dana Desa dll kemudian mererapkan sekaligus mengarsipkannya dengan tertib) | E28: 6 | F28: arsip | O28: 2 | Q28: 2 | R28: 2 | S28: =SUM(N28:R28) -> 6
A29: 5 | B29: Membuat laporan pelaksanaan seluruh kegiatan sesuai bidang tugasnya | C29: b | D29: Tersusunnya laporan pelaksanaan kegiatan kepada Lurah sesuai dengan bidang tugasnya. (contoh: Menyampaikan laporan terkait dengan hasil presentasi/desk rancangan APBKAL, perubahan, dll) | E29: 1 | F29: laporan | O29: 1 | S29: =SUM(N29:R29) -> 1
A30: 6 | B30: Memberikan saran dan pertimbangan kepada Lurah mengenai kebijakan dan tindakan yang akan diambil | C30: a | D30: Memberikan saran dan pertimbangan kepada Lurah mengenai kebijakan dan tindakan yang akan diambil | E30: 6 | F30: kali | P30: 2 | Q30: 2 | R30: 2 | S30: =SUM(N30:R30) -> 6
A31: 7 | B31: Melaksanakan Tugas lain yang diberikan oleh Lurah | C31: a | D31: Terlaksananya tugas disposisi surat, undangan dan/atau tugas lain dari Lurah dan melaporkan hasil pelaksanaannya kepada Lurah. | E31: 2 | F31: kali | O31: 1 | Q31: 1 | S31: =SUM(N31:R31) -> 2
C32: b | D32: Terlaksananya tugas menjadi bagian dalam Tim Pelaksana Kegiatan (TPK), dan/atau Tim lainnya berdasarkan Surat Keputusan. (contoh: Masuk dalam Tim Penyusunan Rencana Kerja Pemerintah Kalurahan) | E32: 1 | F32: tim | O32: 1 | S32: =SUM(N32:R32) -> 1
C33: c | D33: Tersusunnya arsip setiap dokumen dan/atau berkas atas bidang tugasnya (contoh: Mengarsipkan dokumen SPP-SPJ, berita acara, perjanjian, dll pada semua kegiatan bidang tugasnya dengan tertib sehingga apabila dibutuhkan setiap waktu siap untuk disajikan) | E33: 20 | F33: arsip | O33: 5 | P33: 5 | Q33: 5 | R33: 5 | S33: =SUM(N33:R33) -> 20
C34: d | D34: Terlaksananya penyusunan laporan pelaksanaan kegiatan sesuai bidang tugasnya setiap semester dan untuk pertanggungjawaban pelaksanaan APBKAL selama 1 tahun anggaran . (contoh: laporan penggunaan anggaran kegiatan dan sisa anggaran kegiatan, beserta alasannya apabila ada sisa anggaran) | E34: 1 | F34: kali | R34: 1 | S34: =SUM(N34:R34) -> 1
C35: e | D35: Terlaksananya monitoring dan evaluasi program kegiatan sesuai bidang tugasnya dan melaporkannya kepada lurah setiap bulan. (contoh: Melaporkan kepada lurah pelaksanaan program kegiatannya, termasuk permasalahan, hambatan, serta solusinya) | E35: 10 | F35: kali | O35: 3 | P35: 2 | Q35: 3 | R35: 2 | S35: =SUM(N35:R35) -> 10
C36: f | D36: Mengikuti Musyawarah Padukuhan dan atau pertemuan lainnya di tigka padukuhan (Musduk) | E36: 1 | F36: Kali | Q36: 1 | S36: =SUM(N36:R36) -> 1
C37: g | D37: Mengikuti Musyawarah Kalurahan (Muskal) | E37: 1 | F37: kali | O37: 1 | S37: =SUM(N37:R37) -> 1
C38: h | D38: Mengikuti Musyawarah Rencana Pembangunan (Musrenbang) | E38: 1 | F38: kali | O38: 1 | S38: =SUM(N38:R38) -> 1
C39: j | D39: Terlaksananya pelaksanaan tugas lain yang diberikan oleh Lurah selain yang sudah tercantum dalam output kegiatan ini. | E39: 3 | F39: kali | P39: 1 | Q39: 2 | S39: =SUM(N39:R39) -> 3
C40: j | D40: mengikuti rapat koordinasi dan atau apel rutin | E40: 20 | F40: Kali | O40: 5 | P40: 5 | Q40: 5 | R40: 5 | S40: =SUM(N40:R40) -> 20
A42: JUMLAH MASING-MASING BULAN | E42: =SUM(E11:E40) -> 177 | F42: =SUM(F11:F40) -> 0 | G42: =SUM(G11:G39) -> 0 | H42: =SUM(H11:H39) -> 0 | I42: =SUM(I11:I39) -> 0 | J42: =SUM(J11:J39) -> 0 | K42: =SUM(K11:K39) -> 0 | L42: =SUM(L11:L39) -> 0 | M42: =SUM(M11:M39) -> 0 | N42: =SUM(N11:N40) -> 0 | O42: =SUM(O11:O39) -> 39 | P42: =SUM(P11:P39) -> 39 | Q42: =SUM(Q11:Q39) -> 39 | R42: =SUM(R11:R39) -> 40 | S42: =SUM(S11:S40) -> 177
O44: Kalidengen, 10 Agustus 2026
O45: Yang berjanji
B46: LURAH KALIDENGEN | F46: =E42/5 -> 35.4 | O46: DANARTA
...

Sheet ULU-ULU
A1: MATRIK RENCANA KEGIATAN
A3: Nama | C3: : | D3: SARIDI
A4: Jabatan | C4: : | D4: ULU ULU
A6: No. | B6: Rencana kegiatan | D6: Output | E6: Target | S6: Jumlah e s/d p
G7: Jan. | H7: Feb. | I7: Maret | J7: April | K7: Mei | L7: Juni | M7: Juli | N7: Agust. | O7: Sept. | P7: Okt. | Q7: Nov. | R7: Des.
A8: a | B8: b | D8: c | E8: d | G8: e | H8: f | I8: g | J8: h | K8: i | L8: j | M8: k | N8: l | O8: m | P8: n | Q8: o | R8: p | S8: q
A9: 1 | B9: Perencanaan, pelaksanaan, pengendalian dan evaluasi pelaksanaan kegiatan pembangunan dan kemakmuran | C9: a | D9: Tersusunnya Rencana Anggaran Biaya (RAB) dalam perencanaan kegiatan tahun berikutnya maupun Perubahan APBKAL di tahun berjalan. | E9: 12 | F9: Dokumen | O9: 4 | P9: 4 | Q9: 4 | S9: =SUM(N9:R9) -> 12
C10: b | D10: Tersusunnya arsip setiap dokumen dan/atau berkas atas bidang tugasnya (contoh: Mengarsipkan dokumen SPP-SPJ, berita acara, perjanjian, dll pada semua kegiatan bidang tugasnya dengan tertib sehingga apabila dibutuhkan setiap waktu siap untuk disajikan | E10: 25 | F10: Dokumen | O10: 6 | P10: 6 | Q10: 6 | R10: 7 | S10: =SUM(N10:R10) -> 25
C11: c | D11: Pemantauan terhadap Pemanfaatan Lumbung pangan Kalurahan dan melaporkan kepada lurah baik lisan maupun tertulis | E11: 5 | F11: Kali | O11: 1 | P11: 1 | Q11: 1 | R11: 2 | S11: =SUM(N11:R11) -> 5
C12: d | D12: Terlaksananya Monitoring dan Evaluasi terhadap Bantuan dan atau pembanguan yang telah dilaksanakan (Misal Perbaikan Atap TKK PKK, Perkerasan Jalan, Bantuan alat-alat pembuatan pupuk dsb ) dan melaporkan kepada lurah baik lisan maupun tertulis | E12: 10 | F12: Kegiatan | O12: 3 | P12: 2 | Q12: 3 | R12: 2 | S12: =SUM(N12:R12) -> 10
C13: e | D13: Terlaksananya sosialisasi, motivasi dan peningkatan kapasitas masyarakat di bidang ekonomi dan lingkungan hidup. (contoh: penyampaian informasi di dalam forum pertemuan tentang program pembanguanan di desa) | E13: 10 | F13: kali | O13: 2 | P13: 3 | Q13: 3 | R13: 2 | S13: =SUM(N13:R13) -> 10
C14: f | D14: Terlaksananya pendataan dan pengelolaan profil kalurahan di Web/Aplikasi Prodeskel, sinkal dan IDM(Profil Desa/Kelurahan) | E14: 3 | F14: bulan | P14: 2 | R14: 1 | S14: =SUM(N14:R14) -> 3 | T14: Bersama Jagabaya
C15: g | D15: menginisiasi, mengkoordinasi dan atau menghadiri pertemuan lembaga (misal P3A Kelompok Tani, Gapoktan, KWT dll) | E15: 5 | F15: Kali | O15: 1 | P15: 2 | Q15: 1 | R15: 1 | S15: =SUM(N15:R15) -> 5
C16: h | D16: Terlaksananya penyebarluasan informasi rencana tata ruang pada satuan ruang strategis (contoh: menyampaikan di forum pertemuan terkait dengan informasi Tanah Keprabon dan/atau bukan Keprabon di daerah kulon progo sesuai dengan ketentuan yang berlaku) | E16: 1 | F16: kali | O16: 1 | S16: =SUM(N16:R16) -> 1
C17: i | D17: Mengkoordinasi, memantau, memastikan dan atau ikut serta dalam penyusunan Rencana Definitif Kebutuhan Kelompok (RDKK) | E17: 1 | F17: Kali | Q17: 1 | S17: =SUM(N17:R17) -> 1
A18: 2 | B18: Pelaksanaan Kegiatan Anggaran | C18: a | D18: Terlaksananya Informasi Publik Desa baik melalui media online maupun offline (Misal Banner APKal, Realisasi APBkal dll) | E18: 3 | F18: kali | P18: 1 | R18: 2 | S18: =SUM(N18:R18) -> 3
C19: b | D19: Terlaksananya Pembangunan/Rehabilitasi/Peningkatan Perkerasan Jalan Desa | E19: 2 | F19: Bulan | Q19: 2 | S19: =SUM(N19:R19) -> 2
C20: c | D20: Terlaksananya Pembangunan Jaringan Pengairan | E20: 2 | F20: Bulan | O20: 1 | P20: 1 | S20: =SUM(N20:R20) -> 2
C21: d | D21: Terlaksanaya Pengisian Direktur Bumkal | E21: 2 | F21: Bulan | Q21: 2 | S21: =SUM(N21:R21) -> 2
C22: e | D22: Terlaksanaya Bimtek/Pelatihan Pengelolaan Bumkal | E22: 1 | F22: Kali | P22: 1 | S22: =SUM(N22:R22) -> 1
A23: 3 | B23: Pelayanan Sesuai bidang Tugasnya | C23: a | D23: Terlaksananya pelayanan kepada warga masyarakat terkait dengan bidang tugasnya. (contoh: Melayani konsultasi warga tentang tata cara/prosedur persyaratan-persyaratan pengajuan IMB, SKU dll) | E23: 5 | F23: Kali | O23: 2 | P23: 1 | Q23: 1 | R23: 1 | S23: =SUM(N23:R23) -> 5
A24: 4 | B24: Mencari, mengumpulkan, menghimpun dan mengolah serta menyajikan data dan informasi yang berhubungan dengan bidang tugasnya | C24: a | D24: Tersusunnya dan terarsipkannya himpunan informasi mengenai regulasi, dan informasi terbaru sesuai bidang tugasnya, dan melaksanakan serta mengarsipkannya dengan tertib. (contoh: Mencari salinan Perbup Nomor 16 Tahun 2020 tentang Tata Cara Pelaksanaan Kegiatan Pengadaan Barang/Jasa di Kalurahan, kemudian mempelajari, menerapkan dan mengarsipkannya dengan tertib sehingga siap disajikan apabila sewaktu-waktu dibutuhkan) | E24: 2 | F24: produk | Q24: 1 | R24: 1 | S24: =SUM(N24:R24) -> 2
A25: 5 | B25: Membuat laporan pelaksanaan seluruh kegiatan sesuai bidang tugasnya | D25: Tersusunnya laporan pelaksanaan kegiatan Pembanguan per titik kegiatan dan Melaporan kepada lurah melalui Panata Laksana sarta Pangripta tentang hasil pembangunan) kemudian mengarsipkan | E25: 4 | F25: Laporan | O25: 2 | P25: 1 | Q25: 1 | S25: =SUM(N25:R25) -> 4
C26: b | D26: Membuat, mengisi dan mengarsipkan Buku administrasi Pemangunan (Buku Rencana Pembangunan, Buku Kegiatan Pembangunan, Buku Inventaris dan Buku Kader Pembangunan ) | E26: 3 | F26: Buku | R26: 3 | S26: =SUM(N26:R26) -> 3
C27: c | D27: Tersusunnya Laporan Kepada lurah tentang kegiatan yang diikuti (Misal : Hasil rapat, kelompoktani, gapotan, musyawarah musim tanam kemudian mempublikasikan kepada masayarakat baik secara tertulis maupun melalui forum pertemuan | E27: 4 | F27: laporan | O27: 1 | P27: 2 | Q27: 1 | S27: =SUM(N27:R27) -> 4
A28: 6 | B28: Memberikan saran dan pertimbangan kepada Lurah mengenai kebijakan dan tindakan yang akan diambil | C28: a | D28: Terlaksananya penyampaian saran dan pertimbangan kepada Lurah mengenai kebijakan yang akan diambil | E28: 2 | F28: kali | O28: 1 | Q28: 1 | S28: =SUM(N28:R28) -> 2
A29: 7 | B29: Melaksanakan Tugas lain yang diberikan oleh Lurah | C29: a | D29: Terlaksananya tugas disposisi surat, undangan dan/atau tugas lain dari Lurah dan melaporkan hasil pelaksanaannya kepada Lurah. | E29: 10 | F29: laporan | O29: 2 | P29: 3 | Q29: 3 | R29: 2 | S29: =SUM(N29:R29) -> 10
C30: b | D30: Terlaksananya tugas menjadi bagian dalam Tim Pelaksana Kegiatan (TPK), dan/atau Tim lainnya berdasarkan Surat Keputusan. (contoh: Masuk dalam Tim Penyusun RKP Kalurahan) | E30: 2 | F30: tim | O30: 2 | S30: =SUM(N30:R30) -> 2
C31: c | D31: Terlaksanannya pengantaran surat/dokumen berdasarkan tugas yang diberikan oleh Lurah. | E31: 2 | F31: dokumen | P31: 1 | Q31: 1 | S31: =SUM(N31:R31) -> 2
C32: d | D32: Terlaksananya penyusunan laporan pelaksanaan kegiatan sesuai bidang tugasnya setiap semester dan untuk pertanggungjawaban pelaksanaan APBKAL selama 1 tahun anggaran . (contoh: laporan penggunaan anggaran kegiatan dan sisa anggaran kegiatan, beserta alasannya apabila ada sisa anggaran) | E32: 1 | F32: laporan | R32: 1 | S32: =SUM(N32:R32) -> 1
C33: e | D33: Terlaksananya penyusunan dan mengajukan SPP dan SPJ kegiatan kepada bendahara maksimal 5 hari kerja setelah kegiatan selesai dilaksanakan. | E33: 10 | F33: spp | O33: 3 | P33: 3 | Q33: 2 | R33: 2 | S33: =SUM(N33:R33) -> 10
A34: 6 | C34: f | D34: Terlaksananya monitoring dan evaluasi program kegiatan sesuai bidang tugasnya dan melaporkannya kepada lurah setiap bulan. (contoh: Melaporkan kepada lurah pelaksanaan program kegiatannya, termasuk permasalahan, hambatan, serta solusinya) | E34: 10 | F34: laporan | O34: 2 | P34: 2 | Q34: 3 | R34: 3 | S34: =SUM(N34:R34) -> 10
C35: g | D35: Mengikuti Pertemuan Tingkat Padukuhan dan atau Musyawarah Padukuhan (Musduk) | E35: 2 | F35: kali | P35: 1 | R35: 1 | S35: =SUM(N35:R35) -> 2
C36: h | D36: Mengikuti Musyawarah Kalurahan (Muskal) | E36: 1 | F36: kali | O36: 1 | S36: =SUM(N36:R36) -> 1
C37: j | D37: Mengikuti Musyawarah Rencana Pembangunan (Musrenbang) baik tingkat Kalurahan maupun Kapanewon | E37: 2 | F37: kali | O37: 2 | S37: =SUM(N37:R37) -> 2
C38: j | D38: Terlaksananya pelaksanaan tugas lain yang diberikan oleh Lurah selain yang sudah tercantum dalam output kegiatan ini | E38: 10 | F38: kali | O38: 2 | P38: 3 | Q38: 2 | R38: 3 | S38: =SUM(N38:R38) -> 10
C39: k | D39: mengikuti rapat koordinasi dan atau apel rutin | E39: 20 | F39: Kali | O39: 5 | P39: 5 | Q39: 5 | R39: 5 | S39: =SUM(N39:R39) -> 20
C40: l | D40: Penulisan Informasi/berita/artikel tentang kegiatan, potensi atau prestasi sesuai bidang tugasnya. | E40: 5 | F40: kali | O40: 1 | P40: 2 | Q40: 1 | R40: 1 | S40: =SUM(N40:R40) -> 5
A41: JUMLAH MASING-MASING BULAN | E41: =SUM(E9:E40) -> 177 | G41: =SUM(G9:G40) -> 0 | H41: =SUM(H9:H40) -> 0 | I41: =SUM(I9:I40) -> 0 | J41: =SUM(J9:J40) -> 0 | K41: =SUM(K9:K40) -> 0 | L41: =SUM(L9:L40) -> 0 | M41: =SUM(M9:M40) -> 0 | N41: =SUM(N9:N40) -> 0 | ... S41: =SUM(S9:S40) -> 177
O43: Kalidengen , 10 Agustus 2026
...

Sheet JAGABAYA
A1: MATRIK RENCANA KEGIATAN
A3: Nama | C3: : | D3: SUBARNO
A4: Jabatan | C4: : | D4: JAGABAYA
A6: No. | B6: Rencana kegiatan | D6: Output | E6: Target | G6: Waktu | S6: Jumlah e s/d p
G7: Jan. | H7: Feb. | I7: Maret | J7: April | K7: Mei | L7: Juni | M7: Juli | N7: Agust. | O7: Sept. | P7: Okt. | Q7: Nov. | R7: Des.
A8: a | B8: b | D8: c | E8: d | G8: e | H8: f | I8: g | J8: h | K8: i | L8: j | M8: k | N8: l | O8: m | P8: n | Q8: o | R8: p | S8: q
A10: 1 | B10: Perencanaan, pelaksanaan, pengendalian dan evaluasi pelaksanaan kegiatan pemerintahan dan keamanan | C10: a | D10: Tersusunnya Rencana Anggaran Biaya (RAB) dalam perencanaan kegiatan tahun berikutnya maupun Perubahan APBKAL di tahun berjalan. | E10: 5 | F10: kegiatan | O10: 3 | Q10: 2 | S10: =SUM(N10:R10) -> 5
C11: b | D11: Terlaksananya evaluasi manajemen tata praja pemerintahan (evaluasi terhadap pelayanan dan kearsipan) | E11: 2 | F11: kali | O11: 1 | R11: 1 | S11: =SUM(N11:R11) -> 2
C12: c | D12: Terlaksananya penyusun rancangan produk regulasi. (contoh: Menyusun rancangan Peraturan Kaluran, Peraturan Lurah, Surat Keputusan, dll kemudian di sampaikan kepada carik untuk diverifikasi) | E12: 5 | F12: produk | O12: 2 | P12: 2 | R12: 1 | S12: =SUM(N12:R12) -> 5
C13: d | D13: Terlaksanannya pengendalian dan evaluasi kegiatan pembinaan ketentraman dan ketertiban dan melaporkannya kepada lurah. (contoh: Ikut dalam kegiatan penyelesaian permasalahan sosial di masyarakat) | E13: 10 | F13: laporan | O13: 3 | P13: 3 | Q13: 2 | R13: 2 | S13: =SUM(N13:R13) -> 10
C14: e | D14: Terlaksananya Kegiatan Pembinaan terhadap Linmas, Forum Jagawarga | E14: 1 | O14: 1 | S14: =SUM(N14:R14) -> 1
C15: f | D15: Terlaksananya kegiatan Upaya Perlindungan Masyarakat (Misal kegiatan yang dilakukakan linmas, Forum jaga warga. ikut dalam pengamanan terhadap kegiatan keramaian di desa | E15: 5 | F15: laporan | O15: 1 | P15: 1 | Q15: 2 | R15: 1 | S15: =SUM(N15:R15) -> 5
C16: g | D16: Terlaksananya Monitoring kegiatan siskamling | E16: 10 | F16: kali | O16: 2 | P16: 3 | Q16: 3 | R16: 2 | S16: =SUM(N16:R16) -> 10
C17: h | D17: Terlaksanannya koordinasi Pencegahan dan atau penanggulangan bencana. (contoh: Hadir dan aktif berkoordinasi dengan pihak terkait saat terjadi bencana banjir, kebakaran, pohon tumbang) | E17: 9 | F17: kali | O17: 3 | P17: 3 | Q17: 2 | R17: 1 | S17: =SUM(N17:R17) -> 9
C18: i | D18: Updating data kependudukan | E18: 5 | F18: Kali | O18: 1 | P18: 1 | Q18: 1 | R18: 2 | S18: =SUM(N18:R18) -> 5
C19: j | D19: Terlaksananya pengarsipan peta kalurahan yang ada dengan tertib.(Baik Hardcopy maupun Aplikasi/Digital) | E19: 5 | F19: Peta | P19: 2 | Q19: 2 | R19: 1 | S19: =SUM(N19:R19) -> 5
A20: 2 | B20: Kegiatan urusan Keistimewaan bidang pertanahan | C20: a | D20: Terlaksanannya update pencatatan dan Inventaris terkait dengan Pemanfaatan dan Pengelolaan Tanah Kalurahan sebagai Dasar dalam Penyusunan Peraturan Kalurahan tentang Pengelolaan Kekayaan Kalurahan. (contoh: daftar tanah kalurahan beserta pemanfaatannya) | E20: 1 | F20: kali | O20: 1 | S20: =SUM(N20:R20) -> 1
C21: b | D21: Terlaksanannya pengadministrasian tanah kalurahan dan pemanfaatannya serta penyusunan Peraturan Kalurahan terkait dengan tanah kalurahan termasuk fasilitasi permohonan izin gubernur. | E21: 1 | F21: kegiatan | P21: 1 | S21: =SUM(N21:R21) -> 1
A22: 3 | B22: Pelaksanaan kegiatan anggaran | C22: a | D22: Terlaksananya penyusunan laporan pelaksanaan kegiatan sesuai bidang tugasnya setiap semester dan untuk pertanggungjawaban pelaksanaan APBKAL selama 1 tahun anggaran . (contoh: laporan penggunaan anggaran kegiatan dan sisa anggaran kegiatan, beserta alasannya apabila ada sisa anggaran) | E22: 1 | F22: laporan | R22: 1 | S22: =SUM(N22:R22) -> 1
C23: b | D23: Terpenuhinya Kebutuhan Operasional Kantor BPK | E23: 1 | F23: Kegiatan | Q23: 1 | S23: =SUM(N23:R23) -> 1
C24: c | D24: Terlaksannya kegiatan RT RW | E24: 20 | F24: kali | O24: 3 | P24: 5 | Q24: 5 | R24: 6 | S24: =SUM(N24:R24) -> 19
C25: d | D25: Terlaksananya kegiatan Updating Aplikasi Prodeskel, IDM dan Sinkal | E25: 3 | F25: Kegiatan | O25: 1 | P25: 1 | Q25: 1 | S25: =SUM(N25:R25) -> 3
C26: e | D26: Tersusunnya Perjanjian Kinerja Lurah, Laporan Kinarja dan Survei Kepuasan Masyarakat | E26: 3 | F26: Dokumen | R26: 3 | S26: =SUM(N26:R26) -> 3
C27: f | D27: Tersusunya Laporan Penyelenggaraan Pemerintah Kalurahan (LPPK) | E27: 1 | F27: Dokumen | R27: 1 | S27: =SUM(N27:R27) -> 1
C28: g | D28: Terlaksananya pengembangan Sistem Informasi Kalurahan | E28: 2 | F28: bulan | O28: 1 | Q28: 1 | S28: =SUM(N28:R28) -> 2
C29: h | D29: Terlaksananya Pelatihan/Sosialisasi Penanggulangan Bencana | E29: 1 | F29: Kali | P29: 1 | S29: =SUM(N29:R29) -> 1
A30: 4 | B30: Pelayanan sesuai bidang tugasnya | C30: a | D30: Terlaksanannya pelayanan bidang Kependudukan, dan ijin keramaian dll) | E30: 16 | F30: Kali | O30: 4 | P30: 4 | Q30: 4 | R30: 4 | S30: =SUM(N30:R30) -> 16
C31: b | D31: Terlaksananya fasilitasi Pelaksanaan Klarifikasi Pertanahan dan urusan pertanahan lainnya. (contoh: turun waris, hibah, konsolidasi tanah, dll) | E31: 5 | F31: Kali | O31: 1 | P31: 2 | Q31: 1 | R31: 1 | S31: =SUM(N31:R31) -> 5
C32: c | D32: Pelayanan lain sesuai bidang tugasnya selain yang sudah tercantum dalam output kegiatan di atas. | E32: 1 | F32: kali | P32: 1 | S32: =SUM(N32:R32) -> 1
A33: 5 | B33: Mencari, mengumpulkan, menghimpun dan mengolah serta menyajikan data dan informasi yang berhubungan dengan bidang tugasnya | C33: a | D33: Tersusunnya dan terarsipkannya himpunan informasi mengenai regulasi, dan informasi terbaru sesuai bidang tugasnya, dan melaksanakan serta mengarsipkannya dengan tertib.(contoh: Pencarian Pergub Nomor 34 Tahun 2017 kemudian mererapkan dalam pengelolaan dan pemanfaatan tanah kalurahan sekaligus mengarsip) | E33: 5 | F33: produk | O33: 1 | P33: 1 | Q33: 2 | R33: 1 | S33: =SUM(N33:R33) -> 5
A34: 6 | B34: Membuat laporan pelaksanaan seluruh kegiatan sesuai bidang tugasnya | C34: a | D34: Tersusunnya laporan pelaksanaan kegiatan kepada Lurah sesuai dengan bidang tugasnya. (contoh: Menyampaikan laporan baik secara tertulis maupun lisan kepada Lurah setelah melaksanakan penyelesaian permasalahan social yang terjadi di masyarakat) | E34: 1 | F34: laporan | P34: 1 | S34: =SUM(N34:R34) -> 1
A35: 7 | B35: Memberikan saran dan pertimbangan kepada Lurah mengenai kebijakan yang akan diambil | C35: a | D35: Terlaksanannya penyampaian saran dan pertimbangan kepada Lurah mengenai kebijakan yang akan diambil | E35: 2 | F35: kali | O35: 2 | S35: =SUM(N35:R35) -> 2
A36: 8 | B36: Pelaksanaan tugas lain yang diberikan oleh Lurah | C36: a | D36: Terlaksananya tugas disposisi surat, undangan dan/atau tugas lain dari Lurah dan melaporkan hasil pelaksanaannya kepada Lurah. | E36: 1 | F36: laporan | Q36: 1 | S36: =SUM(N36:R36) -> 1
C37: b | D37: Terlaksananya tugas menjadi bagian dalam Tim Pelaksana Kegiatan (TPK), dan/atau Tim lainnya berdasarkan Surat Keputusan. (contoh: Masuk dalam TPK Kegiatan Sistem Informasi Kalurahan) | E37: 1 | F37: tim | O37: 1 | S37: =SUM(N37:R37) -> 1
C38: c | D38: Tersusunnya arsip setiap dokumen dan/atau berkas atas bidang tugasnya (contoh: Mengarsipkan dokumen SPP-SPJ, berita acara, perjanjian, dll pada semua kegiatan bidang tugasnya dengan tertib sehingga apabila dibutuhkan setiap waktu siap untuk disajikan) | E38: 9 | F38: arsip | O38: 3 | P38: 2 | Q38: 2 | R38: 2 | S38: =SUM(N38:R38) -> 9
C39: d | D39: Terlaksanannya pengantaran surat/dokumen berdasarkan tugas yang diberikan oleh Lurah. | E39: 1 | F39: dokumen | O39: 1 | S39: =SUM(N39:R39) -> 1
C40: e | D40: Terlaksananya penyusunan laporan pelaksanaan kegiatan sesuai bidang tugasnya setiap semester dan untuk pertanggungjawaban pelaksanaan APBKAL selama 1 tahun anggaran . (contoh: laporan penggunaan anggaran kegiatan dan sisa anggaran kegiatan, beserta alasannya apabila ada sisa anggaran) | E40: 2 | F40: laporan | R40: 2 | S40: =SUM(N40:R40) -> 2
C41: f | D41: Terlaksananya penyusunan dan mengajukan SPP dan SPJ kegiatan kepada bendahara maksimal 5 hari kerja setelah kegiatan selesai dilaksanakan. | E41: 10 | F41: SPP | O41: 2 | P41: 2 | Q41: 3 | R41: 3 | S41: =SUM(N41:R41) -> 10
C42: g | D42: Terlaksananya monitoring dan evaluasi program kegiatan sesuai bidang tugasnya dan melaporkannya kepada lurah setiap bulan. (contoh: Melaporkan kepada lurah pelaksanaan program kegiatannya, termasuk permasalahan, hambatan, serta solusinya) | E42: 1 | F42: laporan | Q42: 1 | S42: =SUM(N42:R42) -> 1
C43: h | D43: Mengikuti Musyawarah Padukuhan dan atau pertemuan lainnya tingkat padukuhan (Musduk) | E43: 1 | F43: kali | P43: 1 | S43: =SUM(N43:R43) -> 1
...

Sheet PALAPA
A1: MATRIK RENCANA KEGIATAN
A4: Nama | C4: : | D4: AGUS ENDARTO
A5: Jabatan | C5: : | D5: PANATA LAKSANA SARTA PANGRIPTA
A8: No. | B8: Rencana kegiatan | D8: Output | E8: Target | G8: Waktu | S8: Jumlah l s/d p
G9: Jan. | H9: Feb. | I9: Maret | J9: April | K9: Mei | L9: Juni | M9: Juli | N9: Agust. | O9: Sept. | P9: Okt. | Q9: Nov. | R9: Des.
A10: a | B10: b | D10: c | E10: d | G10: e | H10: f | I10: g | J10: h | K10: i | L10: j | M10: k | N10: l | O10: m | P10: n | Q10: o | R10: p | S10: q
A12: 1 | B12: Perencanaan, pelaksanaan, pengendalian dan evaluasi pelaksanaan urusan ketatausahaan, umum dan perencanaan | C12: a | D12: Terlaksanannya pencermatan dan pembuatan surat sesuai tata naskah yang berlaku baik manual maupun melalui aplikasi persyuratan (contoh: membuat surat undangan, surat pengantar pengiriman Peraturan Kalurahan kepada Panewu Pengasih) | E12: 10 | F12: surat/dok. | O12: 3 | P12: 3 | Q12: 2 | R12: 2 | S12: =SUM(N12:R12) -> 10
C13: b | D13: Terlaksananya register surat masuk, baik secara langsung/offline maupun melalui SID/suratku/elektronik), menyampiakan kepada lurah dan atau lainnya serta menyampaikan disposisi surat | E13: 20 | F13: surat/dok. | O13: 5 | P13: 5 | Q13: 5 | R13: 5 | S13: =SUM(N13:R13) -> 20
C14: c | D14: Terlaksananya registrasi surat keluar baik secara langsung/offline maupun melalui SID/suratku/elektronik) dan mengkoordinasi pendistribusianya (contoh: Penulisan nomor pada buku agenda surat keluar kepada Dinas PMD Dalduk dan KB | E14: 20 | F14: surat/dok. | O14: 5 | P14: 5 | Q14: 5 | R14: 5 | S14: =SUM(N14:R14) -> 20
C15: d | D15: Terlaksana register ekspedisi (contoh: Penulisan di buku ekspedisi Surat Dinas kepada Kapanewon Pengasih) | E15: 5 | F15: register | O15: 1 | P15: 1 | Q15: 1 | R15: 2 | S15: =SUM(N15:R15) -> 5
C16: e | D16: Terlaksananya penulisan agenda kegiatan di papan jadwal agenda kegiatan dalam aplikasi online maupan media offline | E16: 5 | F16: agenda | O16: 1 | P16: 2 | Q16: 1 | R16: 1 | S16: =SUM(N16:R16) -> 5
C17: f | D17: Terlaksananya penyiapan rapat (contoh: berkoordinasi dengan staf dan pamong lain yang sekiranya bisa membantu dalam menyiapkan tempat, sarana prasarana, konsumsi, MC, dirijen lagu pada kegiatan musyawarah kalurahan) | E17: 15 | F17: rapat | O17: 4 | P17: 4 | Q17: 3 | R17: 4 | S17: =SUM(N17:R17) -> 15
C18: g | D18: Terlaksananya pencatatan dan inventarisasi aset kalurahan (contoh: menempel stiker nomor di kursi/meja/computer, dll dan dicatatkan di dalam buku aset) | E18: 1 | F18: Kali | R18: 1 | S18: =SUM(N18:R18) -> 1
C19: h | D19: Terlaksananya fasilitasi koordinasi pelayanan umum (contoh: menyampaikan kepada staf dan/atau pamong lain terkait update aturan pelayanan persuratan, update SOP pelayanan, dll) | E19: 1 | F19: kali | O19: 1 | S19: =SUM(N19:R19) -> 1
C20: i | D20: Terlaksananya kegiatan tata usaha, umum dan perencanaan terkait dengan keistimewaan (contoh: Pembuatan proposal usulan terkait Dana Keisimewaaan, pelaksanaan Musyawarah Kalurahan usulan kegiatan yang di danai Dana Keistimewaan) | E20: 1 | O20: 1 | S20: =SUM(N20:R20) -> 1
C21: j | D21: Berkoordinasi dengan Pamong lainnya dan memastikan dokumen administrasi Pamong Kalurahan dilaksanakan sebagaimana peraturan yang berlaku (misal berkoordinasi dengan Ulu-ulu terkait Buku administrasi Pembangunan, berkoordinasi dengan carik terkait buku agenda perkal berkoordinasi dengan Jagabay terkait administrasi pertanahan dll). | E21: 1 | F21: kali | R21: 1 | S21: =SUM(N21:R21) -> 1
C22: k | D22: Terlaksananya penyediaan prasarana kantor kalurahan (contoh: Pemenuhan kebutuhan lampu, kipas angin, cat tembok, dll) | E22: 1 | F22: kegiatan | P22: 1 | S22: =SUM(N22:R22) -> 1
C23: l | D23: Terlaksananya penyediaan prasarana pamong kalurahan (contoh: ATK, alat kebersihan dan alat listrikl) | E23: 1 | F23: kegiatan | Q23: 1 | S23: =SUM(N23:R23) -> 1
C24: m | D24: Terlaksananya input data pamong di aplikasi dan manual (update) (contoh: Mencatat dan melakukan update berkala di buku pamong kalurahan/aparatur pamong kalurahan dan input/update berkala di aplikasi SID maupun SIAPDES maupun aplikasi lainnya yang relevan) | E24: 1 | F24: kali | Q24: 1 | S24: =SUM(N24:R24) -> 1
C25: n | D25: Terlaksananya pembuatan bagan susunan organisasi tata kerja pemerintah kalurahan (update) dan atau Lembaga lainnya | E25: 1 | F25: bagan | P25: 1 | S25: =SUM(N25:R25) -> 1
C26: o | D26: Terlaksanannya pemenuhan kebutuhan kerumahtanggaan pemerintah kalurahan (contoh: koordinasi terkait teknis dalam pemenuhan kebutuhan gula, gas, teh, sabun, dll) | E26: 1 | F26: kegiatan | O26: 1 | S26: =SUM(N26:R26) -> 1
C27: p | D27: Terlaksananya pelaporan aset semester I dan semester II | E27: 1 | F27: laporan | R27: 1 | S27: =SUM(N27:R27) -> 1
C28: q | D28: Tersusunnya Rencana Anggaran Biaya (RAB) dalam perencanaan kegiatan tahun berikutnya maupun Perubahan APBKAL di tahun berjalan. | E28: 2 | F28: kegiatan | P28: 1 | Q28: 1 | S28: =SUM(N28:R28) -> 2
A29: 2 | B29: Melaksanaan kegiatan anggaran | C29: a | D29: Penyaluran siltap dan Jaminan Sosial bagi Lurah dan Pamong* | E29: 5 | F29: bulan | O29: 2 | P29: 1 | Q29: 1 | R29: 1 | S29: =SUM(N29:R29) -> 5 | V29: Melaksanaan kegiatan anggaran
C30: b | D30: Penyediaan Operasional Pemerintah Kalurahan* | E30: 5 | F30: bulan | O30: 1 | P30: 1 | Q30: 1 | R30: 2 | S30: =SUM(N30:R30) -> 5
C31: c | D31: Penyediaan Operasional Pemerintah Kalurahan yang bersumber dari Dana Desa* | E31: 5 | F31: bulan | O31: 1 | P31: 2 | Q31: 1 | R31: 1 | S31: =SUM(N31:R31) -> 5
C32: d | D32: Pembangunan/Rehabilitasi/Peningkatan Gedung/Prasarana Kantor Kalurahan* | E32: 3 | F32: bulan | O32: 1 | P32: 1 | Q32: 1 | S32: =SUM(N32:R32) -> 3
C33: e | D33: Penyelenggaraan Musyawarah Perencanaan Kalurahan/Pembahasan APBKal Kalurahan* | E33: 2 | F33: Kali | O33: 1 | R33: 1 | S33: =SUM(N33:R33) -> 2
C34: t | D34: Penyelenggaraan Musyawarah Kalurahan Lainnya (Musduk, rembug warga dan lain-lain yang bersifat non-reguler)* | E34: 1 | F34: Kali | P34: 1 | S34: =SUM(N34:R34) -> 1
C35: g | D35: Penyusunan Dokumen Perencaan Kalurahan (RPJM Kal./RKP Kal., dll)* | E35: 1 | F35: Dokumen | P35: 1 | S35: =SUM(N35:R35) -> 1
C36: h | D36: Pengelolaan/Administrasi/Inventarisasi/Penilaian Aset Kalurahan* | E36: 1 | F36: bulan | R36: 1 | S36: =SUM(N36:R36) -> 1
C37: i | D37: Melaksanakan perekapan presensi pamong setiap bulan dan melaporkannya | E37: 4 | F37: bulan | O37: 1 | P37: 1 | Q37: 1 | R37: 1 | S37: =SUM(N37:R37) -> 4
C38: j | D38: perjanjian kerja sama dengan penyedia atas pengadaan barang/jasa ( perjanjiann konsultan pembanguan, berkoordinasi dengan ulu-ulu terkait pengadaan meterial pembangunan kantor) | E38: 2 | F38: Dokumen | O38: 2 | S38: =SUM(N38:R38) -> 2
A39: 3 | B39: Mencari, mengumpulkan, menghimpun dan mengolah serta menyajikan data dan informasi yang berhubungan dengan bidang tugasnya | C39: a | D39: Tersusunnya dan terarsipkannya himpunan informasi mengenai regulasi, dan informasi terbaru sesuai bidang tugasnya, dan melaksanakan serta mengarsipkannya dengan tertib. (contoh: Pencarian Peraturan Bupati Kulon Progo Nomor 67 Tahun 2019 tentang Pedoman Tata Naskah Dinas Pemerintah Kalurahan kemudian diterapkan dalam pembuatan surat dinas sekaligus mengarsipkannya dengan tertib) | E39: 2 | F39: produk | P39: 2 | S39: =SUM(N39:R39) -> 2 | V39: Mencari, mengumpulkan, menghimpun dan mengolah serta menyajikan data dan informasi yang berhubungan dengan bidang tugasnya
A40: 4 | B40: Membuat laporan pelaksanaan seluruh kegiatan sesuai bidang tugasnya | C40: a | D40: Tersusunnya laporan pelaksanaan kegiatan kepada Lurah sesuai dengan bidang tugasnya. (laporan pelaksanaan pembangunan kantor) | E40: 1 | F40: laporan | Q40: 1 | S40: =SUM(N40:R40) -> 1 | V40: Membuat laporan pelaksanaan seluruh kegiatan sesuai bidang tugasnya
A41: 5 | B41: Memberikan saran dan pertimbangan kepada Lurah mengenai kebijakan dan tindakan yang akan diambil | C41: a | D41: Terlaksanannya penyampaian saran dan pertimbangan kepada Lurah mengenai kebijakan yang akan diambil | E41: 2 | F41: kegiatan | O41: 1 | R41: 1 | S41: =SUM(N41:R41) -> 2 | V41: Memberikan saran dan pertimbangan kepada Lurah mengenai kebijakan dan tindakan yang akan diambil
A42: 6 | B42: Melaksanaan tugas lain yang diberikan oleh Lurah | C42: a | D42: Terlaksananya tugas disposisi surat, undangan dan/atau tugas lain dari Lurah dan melaporkan hasil pelaksanaannya kepada Lurah. | E42: 1 | F42: laporan | P42: 1 | S42: =SUM(N42:R42) -> 1 | V42: Melaksanaan tugas lain yang diberikan oleh Lurah
C43: b | D43: Terlaksananya tugas menjadi bagian dalam Tim Pelaksana Kegiatan (TPK), dan/atau Tim lainnya berdasarkan Surat Keputusan. (contoh: Masuk dalam Tim Penyusunan RKP Kalurahan) | E43: 3 | F43: tim | O43: 1 | P43: 1 | Q43: 1 | S43: =SUM(N43:R43) -> 3
C44: c | D44: Tersusunnya arsip setiap dokumen dan/atau berkas atas bidang tugasnya (contoh: Mengarsipkan dokumen SPP-SPJ, berita acara, perjanjian, dll pada semua kegiatan bidang tugasnya dengan tertib sehingga apabila dibutuhkan setiap waktu siap untuk disajikan) | E44: 10 | F44: arsip/dok. | O44: 2 | P44: 2 | Q44: 2 | R44: 4 | S44: =SUM(N44:R44) -> 10
C45: d | D45: Terlaksanannya pengantaran surat/dokumen berdasarkan tugas yang diberikan oleh Lurah. | E45: 2 | F45: surat/dok. | G45: =+S45:FG50 -> #VALUE! | O45: 1 | R45: 1 | S45: =SUM(N45:R45) -> 2 | U45: SETIDAKNYA LAP ASET
...

Sheet DUKUH
A1: MATRIK RENCANA KEGIATAN
A3: Nama | D3: : ….................................................
A4: Jabatan | D4: : DUKUH …...................................
A6: No. | B6: Rencana kegiatan | D6: Output | E6: Target | G6: Waktu | S6: Jumlah e s/d p
G7: Jan. | H7: Feb. | I7: Maret | J7: April | K7: Mei | L7: Juni | M7: Juli | N7: Agust. | O7: Sept. | P7: Okt. | Q7: Nov. | R7: Des.
A8: a | B8: b | D8: c | E8: d | G8: e | H8: f | I8: g | J8: h | K8: i | L8: j | M8: k | N8: l | O8: m | P8: n | Q8: o | R8: p | S8: q
A10: 1 | B10: Membantu pelaksanaan tugas Lurah di wilayah Padukuhan | C10: a | D10: Pembinaan Ketentraman dan Ketertiban, mobilitas penduduk, penataan administratif (misal Koordinasi, ikut serta, atau monitoring kegiatan siskamling. Mencatat dan membukukan mobilisasi penduduk) | E10: 20 | F10: Kegiatan | O10: 5 | P10: 5 | Q10: 5 | R10: 5 | S10: =SUM(N10:R10) -> 20
C11: b | D11: Perencanaan, pelaksanaan dan evaluasi pembangunan di wilayahnya ( Misal Koordinasi dengan RT, RW, KKLKMK atau lainnya..) | E11: 1 | F11: kegiatan | P11: 1 | S11: =SUM(N11:R11) -> 1
C12: c | D12: Terlaksananya dan/atau menghadiri kegiatan kerja bakti, dan/atau kegiatan lain terkait dengan upaya menjaga kebersihan dan kesehatan lingkungan di tingkat padukuhan maupun RT. | E12: 5 | F12: kegiatan | O12: 1 | P12: 1 | Q12: 2 | R12: 1 | S12: =SUM(N12:R12) -> 5
C13: d | D13: Terlaksananya dan/atau menghadiri kegiatan persiapan pelaksanaan hajatan di masyarakat. (contoh: pernikahan, lamaran, pengajian, lelayu/pemberangkatan jenazah dan kegiatan masyarakat lainnya) | E13: 10 | F13: kegiatan | O13: 3 | P13: 3 | Q13: 2 | R13: 2 | S13: =SUM(N13:R13) -> 10
C14: e | D14: Terlaksananya pemantauan dan melaporkan kepada lurah terkait dengan penggunaan dan pemanfaatan tanah kalurahan di wilayah masing-masing (contoh: Pemantauan terhadap tanah Kalurahan yang diapaki Fasum/Fasus dan membukukan dalam dalam buku khusus sehingga dapt dibukukan jika terdapat perubahan penggunan | E14: 1 | F14: laporan | R14: 1 | S14: =SUM(N14:R14) -> 1
A15: 2 | B15: Mencari, mengumpulkan, menghimpun dan mengolah serta menyajikan data dan informasi yang berhubungan dengan bidang tugasnya | C15: a | D15: Tersusunnya dan terarsipkannya himpunan informasi mengenai regulasi, dan informasi terbaru sesuai bidang tugasnya, dan melaksanakan serta mengarsipkannya dengan tertib.(misal Mengarsip Perkal, Perbup dan atau mambuat database kependudukan diwilayahnya) | E15: 1 | F15: produk | P15: 1 | S15: =SUM(N15:R15) -> 1
A16: 3 | B16: Membantu pelayanan umum di kantor kalurahan; | C16: a | D16: Terlaksanannya terkait dengan pelayanan di kalurahan (contoh: surat keterangan usaha, surat keterangan domisili, surat keterangan tidak mampu, pengantar pernikahan, dan pelayanan lainnya yang dilayani oleh pemerintah kalurahan) | E16: 20 | F16: surat | O16: 5 | P16: 5 | Q16: 5 | R16: 5 | S16: =SUM(N16:R16) -> 20
A17: 4 | B17: Membuat laporan pelaksanaan seluruh kegiatan sesuai bidang tugasnya | C17: a | D17: Tersusunnya laporan pelaksanaan kegiatan kepada Lurah sesuai dengan bidang tugasnya. (contoh: Menyampaikan laporan baik secara tertulis kepada Lurah setelah melaksanakan penyelesaian permasalahan social yang terjadi di masyarakat, atau kegiatan lainnya baik yaang dianggarak APBKal maupun tidak dianggarkan) | E17: 1 | F17: laporan | R17: 1 | S17: =SUM(N17:R17) -> 1
A18: 5 | B18: Memberikan saran dan pertimbangan kepada Lurah mengenai kebijakan dan tindakan yang akan diambil | C18: a | D18: Terlaksanannya penyampaian saran dan pertimbangan kepada Lurah mengenai kebijakan yang akan diambil | E18: 2 | F18: kali | O18: 1 | R18: 1 | S18: =SUM(N18:R18) -> 2
A19: 6 | B19: Melaksanakan Tugas lain yang diberikan oleh Lurah | C19: a | D19: Terlaksananya tugas disposisi surat, undangan dan/atau tugas lain dari Lurah dan melaporkan hasil pelaksanaannya kepada Lurah. (termasuk Undangan Kalurahan atau kapanewon) | E19: 10 | F19: Kali | O19: 2 | P19: 3 | Q19: 3 | R19: 2 | S19: =SUM(N19:R19) -> 10
C20: b | D20: Terlaksananya tugas menjadi bagian dalam Tim Pelaksana Kegiatan (TPK), dan/atau Tim lainnya berdasarkan Surat Keputusan. (contoh: Masuk dalam TPK Kegiatan Posyandu, dll) | E20: 1 | F20: tim | Q20: 1 | S20: =SUM(N20:R20) -> 1
C21: c | D21: Tersusunnya arsip setiap dokumen dan/atau berkas atas bidang tugasnya (contoh: Mengarsipkan dokumen SPP-SPJ, berita acara, perjanjian, dll pada semua kegiatan bidang tugasnya dengan tertib sehingga apabila dibutuhkan setiap waktu siap untuk disajikan) | E21: 5 | F21: arsip | O21: 1 | P21: 2 | Q21: 1 | R21: 1 | S21: =SUM(N21:R21) -> 5
C22: d | D22: Terlaksanannya pengantaran dan/atau pengambilan surat/dokumen terkait dengan tugas kedinasan. | E22: 20 | F22: dokumen | O22: 4 | P22: 4 | Q22: 6 | R22: 6 | S22: =SUM(N22:R22) -> 20
C23: e | D23: Terlaksananya monitoring dan evaluasi program kegiatan sesuai bidang tugasnya dan melaporkannya kepada lurah setiap bulan. (contoh: Melakukan evaluasi terhadap kegiatan yang dilakukakan di wilayahnua dan Melaporkan kepada lurah, termasuk permasalahan, hambatan, serta solusinya) | E23: 1 | F23: laporan | O23: 1 | S23: =SUM(N23:R23) -> 1
C24: f | D24: Mengadakan Musyawarah Padukuhan (Musduk) dan atau pertemuan lainnya | E24: 2 | F24: kali | O24: 1 | Q24: 1 | S24: =SUM(N24:R24) -> 2
C25: g | D25: Mengikuti Musyawarah Kalurahan (Muskal) | E25: 1 | F25: kali | O25: 1 | S25: =SUM(N25:R25) -> 1
C26: h | D26: Mengikuti Musyawarah Rencana Pembangunan (Musrenbang) | E26: 1 | F26: kali | O26: 1 | S26: =SUM(N26:R26) -> 1
C27: i | D27: Terlaksanannya sambutan atau sebutan lainnya di acara hajatan di masyarakat (contoh: pernikahan, lamaran, pengajian, lelayu/pemberangkatan jenazah dan kegiatan masyarakat lainnya) | E27: 10 | F27: acara | O27: 2 | P27: 3 | Q27: 3 | R27: 2 | S27: =SUM(N27:R27) -> 10 | V27: Melaksanaan kegiatan anggaran
C28: j | D28: Terlaksanannya pengkondisian permasalahan dan/atau bencana yang terjadi di wilayahnya selanjutnya melaporkan kepada lurah (contoh: banjir, tanah longsor, masalah sosial kemasyarakatan, dll) | E28: 5 | F28: kali | O28: 2 | P28: 1 | Q28: 1 | R28: 1 | S28: =SUM(N28:R28) -> 5
C29: k | D29: Terlaksananya pendampingan pengantaran ODGJ, Donor darah atau Pengobatan | E29: 1 | F29: kali | P29: 1 | S29: =SUM(N29:R29) -> 1
C30: l | D30: Terlaksananya pelaksanaan tugas lain yang diberikan oleh Lurah selain yang sudah tercantum dalam output kegiatan ini dan melaporakan hasil pelaksanaannya kepada lurah. | E30: 10 | F30: kali | O30: 3 | P30: 2 | Q30: 2 | R30: 3 | S30: =SUM(N30:R30) -> 10
C31: m | D31: mengikuti rapat koordinasi dan atau apel rutin | E31: 20 | F31: Kali | O31: 5 | P31: 5 | Q31: 5 | R31: 5 | S31: =SUM(N31:R31) -> 20
C32: n | D32: Tercapainya Pembayaran PBB-P2 (non-Tanah Desa) di Padukuhan dalam (5 SPPT=1 poin). | E32: 10 | F32: poin | O32: 2 | P32: 3 | Q32: 2 | R32: 2 | S32: =SUM(N32:R32) -> 9
A33: JUMLAH MASING-MASING BULAN | E33: =SUM(E10:E32) -> 158 | F33: =SUM(F10:F32) -> 0 | G33: =SUM(G10:G32) -> 0 | H33: =SUM(H10:H32) -> 0 | I33: =SUM(I10:I32) -> 0 | J33: =SUM(J10:J32) -> 0 | K33: =SUM(K10:K32) -> 0 | L33: =SUM(L10:L32) -> 0 | ... S33: =SUM(S10:S32) -> 157
O35: Kalidengen, 10 Agustus 2026
O36: Yang berjanji
B37: LURAH KALIDENGEN | O37: DUKUH …...............................................
B40: =CARIK!B46 -> SUNARDI | O40: ….....................................................
G53: =326*75% -> 244.5 | H53: =G53/5 -> 48.9

Sheet STAF
A1: MATRIK RENCANA KEGIATAN
A3: Nama | D3: : ….................................................
A4: Jabatan | D4: : STAF PAMONG
A6: No. | B6: Rencana kegiatan | D6: Output | E6: Target | G6: Waktu | S6: Jumlah e s/d p
G7: Jan. | H7: Feb. | I7: Maret | J7: April | K7: Mei | L7: Juni | M7: Juli | N7: Agust. | O7: Sept. | P7: Okt. | Q7: Nov. | R7: Des.
